<?xml version="1.0" ?>
<!-- =================================================================================== -->
<!-- |    This document was autogenerated by xacro from robot.urdf.xacro               | -->
<!-- |    EDITING THIS FILE BY HAND IS NOT RECOMMENDED                                 | -->
<!-- =================================================================================== -->
<robot name="tankbot_robot">
  <!-- Specify some standard inertial calculations https://en.wikipedia.org/wiki/List_of_moments_of_inertia -->
  <!-- These make use of xacro's mathematical functionality -->
  <material name="white">
    <color rgba="1 1 1 1"/>
  </material>
  <material name="blue">
    <color rgba="0 0 1 1"/>
  </material>
  <material name="brown">
    <color rgba="0.918 0.867 0.792 1"/>
  </material>
  <material name="black">
    <color rgba="0 0 0 1"/>
  </material>
  <material name="green">
    <color rgba="0 1 0 1"/>
  </material>
  <link name="base_link">
    </link>
  <joint name="chassis_joint" type="fixed">
    <parent link="base_link"/>
    <child link="chassis"/>
    <origin xyz="-0.1 0 0"/>
  </joint>
  <link name="chassis">
    <visual>
      <origin xyz="0.10125 0 0.010"/>
      <geometry>
        <mesh filename="package://tankbot/meshes/chassis.stl"/>
      </geometry>
      <material name="brown"/>
    </visual>
    <collision>
      <origin xyz="0.1015 0 0.05"/>
      <geometry>
        <box size="0.215 0.201 0.10"/>
      </geometry>
    </collision>
    <inertial>
      <mass value="1"/>
      <inertia ixx="0.00556875" ixy="0.0" ixz="0.00489336" iyy="0.025445" iyz="0.0" izz="0.0276345"/>
    </inertial>
  </link>
  <gazebo reference="chassis">
    <material>Gazebo/Blue</material>
  </gazebo>
  <joint name="left_wheel_joint" type="continuous">
    <parent link="base_link"/>
    <child link="left_wheel"/>
    <origin rpy="-1.5707963267948966 0 0" xyz="0 0.1105 0.044"/>
    <axis xyz="0 0 1"/>
  </joint>
  <link name="left_wheel">
    <visual>
      <geometry>
        <mesh filename="package://tankbot/meshes/left_wheel_link.stl"/>
      </geometry>
      <material name="white"/>
    </visual>
    <collision>
      <geometry>
        <cylinder length="0.02" radius="0.052"/>
      </geometry>
    </collision>
    <inertial>
      <origin rpy="0 0 0" xyz="0 0 0"/>
      <mass value="0.08"/>
      <inertia ixx="5.6746666666666656e-05" ixy="0.0" ixz="0.0" iyy="5.6746666666666656e-05" iyz="0.0" izz="0.00010816"/>
    </inertial>
  </link>
  <gazebo reference="left_wheel">
    <material>Gazebo/White</material>
  </gazebo>
  <joint name="right_wheel_joint" type="continuous">
    <parent link="base_link"/>
    <child link="right_wheel"/>
    <origin rpy="1.5707963267948966 0 0" xyz="0 -0.10 0.044"/>
    <axis xyz="0 0 -1"/>
  </joint>
  <link name="right_wheel">
    <visual>
      <geometry>
        <mesh filename="package://tankbot/meshes/right_wheel_link.stl"/>
      </geometry>
      <material name="white"/>
    </visual>
    <collision>
      <geometry>
        <cylinder length="0.02" radius="0.052"/>
      </geometry>
    </collision>
    <inertial>
      <origin rpy="0 0 0" xyz="0 0 0"/>
      <mass value="0.08"/>
      <inertia ixx="5.6746666666666656e-05" ixy="0.0" ixz="0.0" iyy="5.6746666666666656e-05" iyz="0.0" izz="0.00010816"/>
    </inertial>
  </link>
  <gazebo reference="right_wheel">
    <material>Gazebo/White</material>
  </gazebo>
  <joint name="caster_wheel_joint" type="fixed">
    <parent link="chassis"/>
    <child link="caster_wheel"/>
    <origin xyz="0.189 0 -0.0025"/>
  </joint>
  <link name="caster_wheel">
    <visual>
      <geometry>
        <sphere radius="0.005"/>
      </geometry>
      <material name="black"/>
    </visual>
    <collision>
      <geometry>
        <sphere radius="0.005"/>
      </geometry>
    </collision>
    <inertial>
      <origin rpy="0 0 0" xyz="0 0 0"/>
      <mass value="0.004"/>
      <inertia ixx="4e-08" ixy="0.0" ixz="0.0" iyy="4e-08" iyz="0.0" izz="4e-08"/>
    </inertial>
  </link>
  <gazebo reference="caster_wheel">
    <material>Gazebo/Black</material>
    <mu1 value="0.0001"/>
    <mu2 value="0.0001"/>
  </gazebo>
  <joint name="caster_wheel_back_left_joint" type="fixed">
    <parent link="chassis"/>
    <child link="caster_wheel_back_left"/>
    <origin xyz="0.0075 0.1337 -0.002"/>
  </joint>
  <link name="caster_wheel_back_left">
    <visual>
      <geometry>
        <sphere radius="0.0065"/>
      </geometry>
      <material name="black"/>
    </visual>
    <collision>
      <geometry>
        <sphere radius="0.0065"/>
      </geometry>
    </collision>
    <inertial>
      <origin rpy="0 0 0" xyz="0 0 0"/>
      <mass value="0.005"/>
      <inertia ixx="8.45e-08" ixy="0.0" ixz="0.0" iyy="8.45e-08" iyz="0.0" izz="8.45e-08"/>
    </inertial>
  </link>
  <gazebo reference="caster_wheel_back_left">
    <material>Gazebo/Black</material>
    <mu1 value="0.0001"/>
    <mu2 value="0.0001"/>
  </gazebo>
  <joint name="caster_wheel_back_right_joint" type="fixed">
    <parent link="chassis"/>
    <child link="caster_wheel_back_right"/>
    <origin xyz="0.0075 -0.1337 -0.002"/>
  </joint>
  <link name="caster_wheel_back_right">
    <visual>
      <geometry>
        <sphere radius="0.0065"/>
      </geometry>
      <material name="black"/>
    </visual>
    <collision>
      <geometry>
        <sphere radius="0.0065"/>
      </geometry>
    </collision>
    <inertial>
      <origin rpy="0 0 0" xyz="0 0 0"/>
      <mass value="0.005"/>
      <inertia ixx="8.45e-08" ixy="0.0" ixz="0.0" iyy="8.45e-08" iyz="0.0" izz="8.45e-08"/>
    </inertial>
  </link>
  <gazebo reference="caster_wheel_back_right">
    <material>Gazebo/Black</material>
    <mu1 value="0.0001"/>
    <mu2 value="0.0001"/>
  </gazebo>
  <gazebo>
    <plugin filename="libgazebo_ros_diff_drive.so" name="diff_drive">
      <!-- Wheel Information -->
      <left_joint>left_wheel_joint</left_joint>
      <right_joint>right_wheel_joint</right_joint>
      <wheel_separation>0.21</wheel_separation>
      <wheel_diameter>0.104</wheel_diameter>
      <!-- Limits -->
      <max_wheel_torque>200</max_wheel_torque>
      <max_wheel_acceleration>10.0</max_wheel_acceleration>
      <!-- Output -->
      <odometry_frame>odom</odometry_frame>
      <robot_base_frame>base_link</robot_base_frame>
      <publish_odom>true</publish_odom>
      <publish_odom_tf>true</publish_odom_tf>
      <publish_wheel_tf>true</publish_wheel_tf>
    </plugin>
  </gazebo>
</robot>
