<?xml version="1.0"?>
<robot xmlns:xacro="http://www.ros.org/wiki/xacro">

    <xacro:include filename="inertial_macros.xacro" />

    <material name="white">
        <color rgba ="1 1 1 1"/>
    </material>

    <material name="blue">
        <color rgba ="0 0 1 1"/>
    </material>
    
    <material name="brown">
        <color rgba ="0.918 0.867 0.792 1"/>
    </material>

    <material name="black">
        <color rgba ="0 0 0 1"/>
    </material>

    <material name="green">
        <color rgba ="0 1 0 1"/>
    </material>

    <link name="base_link">
    </link>

    <joint name="chassis_joint" type="fixed">
        <parent link="base_link"/>
        <child link="chassis"/>
        <origin xyz="-0.1 0 0"/>
    </joint>

    <link name="chassis">
        <visual>
            <origin xyz="0.10125 0 0.010"/>
            <geometry>
                <mesh filename="package://tankbot/meshes/chassis.stl"/>
            </geometry>
            <material name="brown"/>
        </visual>
        <collision>
            <origin xyz="0.1015 0 0.05"/>
            <geometry>
                <box size="0.215 0.201 0.10" />
            </geometry>
            <origin xyz="-0.01 0 0.01"/>
            <geometry>
                <box size="0.01 0.01 0.01" />
            </geometry>

        </collision>
        <inertial>
            <mass value="1"/>
            <inertia ixx="0.00556875" ixy="0.0" ixz="0.00489336" iyy="0.025445" iyz="0.0" izz="0.0276345"/>
        </inertial>
    </link>

    <gazebo reference="chassis">
        <material>Gazebo/Blue</material>
    </gazebo>

    <joint name="left_wheel_joint" type="continuous">
        <parent link="base_link"/>
        <child link="left_wheel"/>
        <origin xyz="0 0.105 0.044" rpy="-${pi/2} 0 0"/>
        <axis xyz="0 0 1"/>
    </joint>

    <link name="left_wheel">
        <visual>
            <geometry>
                <mesh filename="package://tankbot/meshes/left_wheel_link.stl"/>
            </geometry>
            <material name="white"/>
        </visual>
        <collision>
            <origin xyz="0 0.0 0.005"/>
            <geometry>
                <cylinder radius="0.052" length="0.02"/>
            </geometry>
        </collision>
        <xacro:inertial_cylinder mass="0.08" length="0.02" radius="0.052">
            <origin xyz="0 0 0" rpy="0 0 0"/>
        </xacro:inertial_cylinder>
    </link>
    <gazebo reference="left_wheel">
        <material>Gazebo/White</material>
    </gazebo>


    <joint name="right_wheel_joint" type="continuous">
        <parent link="base_link"/>
        <child link="right_wheel"/>
        <origin xyz="0 -0.105 0.044" rpy="${pi/2} 0 0"/>
        <axis xyz="0 0 -1"/>
    </joint>

    <link name="right_wheel">
        <visual>
            <geometry>
                <mesh filename="package://tankbot/meshes/right_wheel_link.stl"/>
            </geometry>
            <material name="white"/>
        </visual>
        <collision>
            <origin xyz="0 0.0 0.005"/>
            <geometry>
                <cylinder radius="0.052" length="0.02"/>
            </geometry>
        </collision>
        <xacro:inertial_cylinder mass="0.08" length="0.02" radius="0.052">
            <origin xyz="0 0 0" rpy="0 0 0"/>
        </xacro:inertial_cylinder>
    </link>
    <gazebo reference="right_wheel">
        <material>Gazebo/White</material>
    </gazebo>

    <joint name="caster_wheel_joint" type="fixed">
        <parent link="chassis"/>
        <child link="caster_wheel"/>
        <origin xyz="0.189 0 -0.0025" />
    </joint>

    <link name="caster_wheel">
        <visual>
            <geometry>
                <sphere radius="0.005"/>
            </geometry>
            <material name="black"/>
        </visual>
        <collision>
            <geometry>
                <sphere radius="0.005"/>
            </geometry>
        </collision>
        <xacro:inertial_sphere mass="0.004" radius="0.005">
            <origin xyz="0 0 0" rpy="0 0 0"/>
        </xacro:inertial_sphere>
    </link>
    <gazebo reference="caster_wheel">
        <material>Gazebo/Black</material>
        <mu1 value="0.0001"/>
        <mu2 value="0.0001"/>
    </gazebo>

        <joint name="caster_wheel_back_left_joint" type="fixed">
        <parent link="chassis"/>
        <child link="caster_wheel_back_left"/>
        <origin xyz="0.0075 0.1337 -0.002" />
    </joint>

    <link name="caster_wheel_back_left">
        <visual>
            <geometry>
                <sphere radius="0.0065"/>
            </geometry>
            <material name="black"/>
        </visual>
        <collision>
            <geometry>
                <sphere radius="0.0065"/>
            </geometry>
        </collision>
        <xacro:inertial_sphere mass="0.005" radius="0.0065">
            <origin xyz="0 0 0" rpy="0 0 0"/>
        </xacro:inertial_sphere>
    </link>
    <gazebo reference="caster_wheel_back_left">
        <material>Gazebo/Black</material>
        <mu1 value="0.0001"/>
        <mu2 value="0.0001"/>
    </gazebo>


    <joint name="caster_wheel_back_right_joint" type="fixed">
        <parent link="chassis"/>
        <child link="caster_wheel_back_right"/>
        <origin xyz="0.0075 -0.1337 -0.002" />
    </joint>

    <link name="caster_wheel_back_right">
        <visual>
            <geometry>
                <sphere radius="0.0065"/>
            </geometry>
            <material name="black"/>
        </visual>
        <collision>
            <geometry>
                <sphere radius="0.0065"/>
            </geometry>
        </collision>
        <xacro:inertial_sphere mass="0.005" radius="0.0065">
            <origin xyz="0 0 0" rpy="0 0 0"/>
        </xacro:inertial_sphere>
    </link>

   <gazebo reference="caster_wheel_back_right">
        <material>Gazebo/Black</material>
        <mu1 value="0.0001"/>
        <mu2 value="0.0001"/>
    </gazebo>

</robot>