<?xml version="1.0" ?>
<!-- =================================================================================== -->
<!-- |    This document was autogenerated by xacro from robot.urdf.xacro               | -->
<!-- |    EDITING THIS FILE BY HAND IS NOT RECOMMENDED                                 | -->
<!-- =================================================================================== -->
<robot name="tankbot">
  <!-- Specify some standard inertial calculations https://en.wikipedia.org/wiki/List_of_moments_of_inertia -->
  <!-- These make use of xacro's mathematical functionality -->
  <material name="white">
    <color rgba="1 1 1 1"/>
  </material>
  <material name="blue">
    <color rgba="0 0 1 1"/>
  </material>
  <material name="brown">
    <color rgba="0.918 0.867 0.792 1"/>
  </material>
  <material name="black">
    <color rgba="0 0 0 1"/>
  </material>
  <material name="green">
    <color rgba="0 1 0 1"/>
  </material>
  <link name="base_link">
    </link>
  <joint name="chassis_joint" type="fixed">
    <parent link="base_link"/>
    <child link="chassis"/>
    <origin xyz="-0.1 0 0"/>
  </joint>
  <link name="chassis">
    <visual>
      <origin xyz="0.10125 0 0.010"/>
      <geometry>
        <mesh filename="package://tankbot/meshes/chassis.stl"/>
      </geometry>
      <material name="brown"/>
    </visual>
    <collision>
      <origin xyz="0.1015 0 0.05"/>
      <geometry>
        <box size="0.215 0.201 0.10"/>
      </geometry>
      <origin xyz="-0.01 0 0.01"/>
      <geometry>
        <box size="0.01 0.01 0.01"/>
      </geometry>
    </collision>
    <inertial>
      <mass value="1"/>
      <inertia ixx="0.00556875" ixy="0.0" ixz="0.00489336" iyy="0.025445" iyz="0.0" izz="0.0276345"/>
    </inertial>
  </link>
  <gazebo reference="chassis">
    <material>Gazebo/Blue</material>
  </gazebo>
  <joint name="left_wheel_joint" type="continuous">
    <parent link="base_link"/>
    <child link="left_wheel"/>
    <origin rpy="-1.5707963267948966 0 0" xyz="0 0.105 0.044"/>
    <axis xyz="0 0 1"/>
  </joint>
  <link name="left_wheel">
    <visual>
      <geometry>
        <mesh filename="package://tankbot/meshes/left_wheel_link.stl"/>
      </geometry>
      <material name="white"/>
    </visual>
    <collision>
      <origin xyz="0 0.0 0.005"/>
      <geometry>
        <cylinder length="0.02" radius="0.052"/>
      </geometry>
    </collision>
    <inertial>
      <origin rpy="0 0 0" xyz="0 0 0"/>
      <mass value="0.08"/>
      <inertia ixx="5.6746666666666656e-05" ixy="0.0" ixz="0.0" iyy="5.6746666666666656e-05" iyz="0.0" izz="0.00010816"/>
    </inertial>
  </link>
  <gazebo reference="left_wheel">
    <material>Gazebo/White</material>
  </gazebo>
  <joint name="right_wheel_joint" type="continuous">
    <parent link="base_link"/>
    <child link="right_wheel"/>
    <origin rpy="1.5707963267948966 0 0" xyz="0 -0.105 0.044"/>
    <axis xyz="0 0 -1"/>
  </joint>
  <link name="right_wheel">
    <visual>
      <geometry>
        <mesh filename="package://tankbot/meshes/right_wheel_link.stl"/>
      </geometry>
      <material name="white"/>
    </visual>
    <collision>
      <origin xyz="0 0.0 0.005"/>
      <geometry>
        <cylinder length="0.02" radius="0.052"/>
      </geometry>
    </collision>
    <inertial>
      <origin rpy="0 0 0" xyz="0 0 0"/>
      <mass value="0.08"/>
      <inertia ixx="5.6746666666666656e-05" ixy="0.0" ixz="0.0" iyy="5.6746666666666656e-05" iyz="0.0" izz="0.00010816"/>
    </inertial>
  </link>
  <gazebo reference="right_wheel">
    <material>Gazebo/White</material>
  </gazebo>
  <joint name="caster_wheel_joint" type="fixed">
    <parent link="chassis"/>
    <child link="caster_wheel"/>
    <origin xyz="0.189 0 -0.0025"/>
  </joint>
  <link name="caster_wheel">
    <visual>
      <geometry>
        <sphere radius="0.005"/>
      </geometry>
      <material name="black"/>
    </visual>
    <collision>
      <geometry>
        <sphere radius="0.005"/>
      </geometry>
    </collision>
    <inertial>
      <origin rpy="0 0 0" xyz="0 0 0"/>
      <mass value="0.004"/>
      <inertia ixx="4e-08" ixy="0.0" ixz="0.0" iyy="4e-08" iyz="0.0" izz="4e-08"/>
    </inertial>
  </link>
  <gazebo reference="caster_wheel">
    <material>Gazebo/Black</material>
    <mu1 value="0.0001"/>
    <mu2 value="0.0001"/>
  </gazebo>
  <joint name="caster_wheel_back_left_joint" type="fixed">
    <parent link="chassis"/>
    <child link="caster_wheel_back_left"/>
    <origin xyz="0.0075 0.1337 -0.002"/>
  </joint>
  <link name="caster_wheel_back_left">
    <visual>
      <geometry>
        <sphere radius="0.0065"/>
      </geometry>
      <material name="black"/>
    </visual>
    <collision>
      <geometry>
        <sphere radius="0.0065"/>
      </geometry>
    </collision>
    <inertial>
      <origin rpy="0 0 0" xyz="0 0 0"/>
      <mass value="0.005"/>
      <inertia ixx="8.45e-08" ixy="0.0" ixz="0.0" iyy="8.45e-08" iyz="0.0" izz="8.45e-08"/>
    </inertial>
  </link>
  <gazebo reference="caster_wheel_back_left">
    <material>Gazebo/Black</material>
    <mu1 value="0.0001"/>
    <mu2 value="0.0001"/>
  </gazebo>
  <joint name="caster_wheel_back_right_joint" type="fixed">
    <parent link="chassis"/>
    <child link="caster_wheel_back_right"/>
    <origin xyz="0.0075 -0.1337 -0.002"/>
  </joint>
  <link name="caster_wheel_back_right">
    <visual>
      <geometry>
        <sphere radius="0.0065"/>
      </geometry>
      <material name="black"/>
    </visual>
    <collision>
      <geometry>
        <sphere radius="0.0065"/>
      </geometry>
    </collision>
    <inertial>
      <origin rpy="0 0 0" xyz="0 0 0"/>
      <mass value="0.005"/>
      <inertia ixx="8.45e-08" ixy="0.0" ixz="0.0" iyy="8.45e-08" iyz="0.0" izz="8.45e-08"/>
    </inertial>
  </link>
  <gazebo reference="caster_wheel_back_right">
    <material>Gazebo/Black</material>
    <mu1 value="0.0001"/>
    <mu2 value="0.0001"/>
  </gazebo>
  <ros2_control name="GazeboSystem" type="system">
    <hardware>
      <plugin>gazebo_ros2_control/GazeboSystem</plugin>
    </hardware>
    <joint name="left_wheel_joint">
      <!-- command interface for left joint -->
      <command_interface name="velocity">
        <param name="min">-10</param>
        <param name="min">10</param>
      </command_interface>
      <!-- state interfaces for left joint -->
      <state_interface name="velocity"/>
      <state_interface name="position"/>
    </joint>
    <joint name="right_wheel_joint">
      <!-- command interface for right joint -->
      <command_interface name="velocity">
        <param name="min">-10</param>
        <param name="min">10</param>
      </command_interface>
      <!-- state interfaces for right joint -->
      <state_interface name="velocity"/>
      <state_interface name="position"/>
    </joint>
  </ros2_control>
  <gazebo>
    <plugin filename="libgazebo_ros2_control.so" name="gazebo_ros2_control">
      <parameters>/home/amirbahador/Documents/tank_ws/install/tankbot/share/tankbot/config/gazebo_controller_tankbot.yaml</parameters>
    </plugin>
  </gazebo>
  <joint name="laser_joint" type="fixed">
    <parent link="chassis"/>
    <child link="laser_frame"/>
    <origin rpy="0 0 0" xyz="0.035 0 0.165"/>
  </joint>
  <link name="laser_frame">
    <visual>
      <origin xyz="0.066 0 -0.155"/>
      <geometry>
        <mesh filename="package://tankbot/meshes/lidar.STL"/>
      </geometry>
      <material name="black"/>
    </visual>
    <collision>
      <origin xyz="0 0 -0.03"/>
      <geometry>
        <cylinder length="0.055" radius="0.035"/>
      </geometry>
    </collision>
    <inertial>
      <origin rpy="0 0 0" xyz="0 0 0"/>
      <mass value="0.08"/>
      <inertia ixx="5.6746666666666656e-05" ixy="0.0" ixz="0.0" iyy="5.6746666666666656e-05" iyz="0.0" izz="0.00010816"/>
    </inertial>
  </link>
  <gazebo reference="laser_frame">
    <material>Gazebo/Black</material>
    <sensor name="laser" type="ray">
      <pose> 0 0 0 0 0 0 </pose>
      <visualize>true</visualize>
      <update_rate>10</update_rate>
      <ray>
        <scan>
          <horizontal>
            <samples>360</samples>
            <min_angle>-3.14</min_angle>
            <max_angle>3.14</max_angle>
          </horizontal>
        </scan>
        <range>
          <min>0.3</min>
          <max>12</max>
        </range>
      </ray>
      <plugin filename="libgazebo_ros_ray_sensor.so" name="laser_controller">
        <ros>
          <argument>~/out:=scan</argument>
        </ros>
        <output_type>sensor_msgs/LaserScan</output_type>
        <frame_name>laser_frame</frame_name>
      </plugin>
    </sensor>
  </gazebo>
  <joint name="camera_joint" type="fixed">
    <parent link="chassis"/>
    <child link="camera_frame"/>
    <origin rpy="0 0 0" xyz="0.195 0 0.095"/>
  </joint>
  <link name="camera_frame">
    <visual>
      <origin xyz="-0.094 0 -0.085"/>
      <geometry>
        <mesh filename="package://tankbot/meshes/camera.STL"/>
      </geometry>
      <material name="blue"/>
    </visual>
    <collision>
      <origin rpy="0 0 0" xyz="-0.005 0 0"/>
      <geometry>
        <box size="0.035 0.035 0.035"/>
      </geometry>
    </collision>
    <inertial>
      <origin rpy="0 0 0" xyz="0 0 0"/>
      <mass value="0.02"/>
      <inertia ixx="4.083333333333334e-06" ixy="0.0" ixz="0.0" iyy="4.083333333333334e-06" iyz="0.0" izz="4.083333333333334e-06"/>
    </inertial>
  </link>
  <joint name="camera_optical_joint" type="fixed">
    <parent link="camera_frame"/>
    <child link="camera_optical_link"/>
    <origin rpy="-1.5707963267948966 0 -1.5707963267948966" xyz="0 0 0.0125"/>
  </joint>
  <link name="camera_optical_link"/>
  <gazebo reference="camera_frame">
    <material>Gazebo/White</material>
    <sensor name="camera" type="camera">
      <pose> 0 0 0 0 0 0 </pose>
      <visualize>true</visualize>
      <update_rate>10</update_rate>
      <camera>
        <horizontal_fov>1.089</horizontal_fov>
        <image>
          <format>R8G8B8</format>
          <width>640</width>
          <height>480</height>
        </image>
        <clip>
          <near>0.05</near>
          <far>8.0</far>
        </clip>
      </camera>
      <plugin filename="libgazebo_ros_camera.so" name="camera_controller">
        <frame_name>camera_optical_link</frame_name>
      </plugin>
    </sensor>
  </gazebo>
</robot>
<!-- xacro robot.urdf.xacro > tankbot.urdf -->
<!-- gz sdf -p tankbot.urdf > model.sdf -->
